<?xml version="1.0"?>
<robot name="cafe_robot">
  <link name="base_link">
    <visual>
      <geometry>
        <box size="0.5 0.3 0.2"/>
      </geometry>
      <material name="blue">
        <color rgba="0 0 1 1"/>
      </material>
    </visual>
  </link>
  <link name="wheel_left">
    <visual>
      <geometry>
        <cylinder radius="0.05" length="0.02"/>
      </geometry>
      <material name="black">
        <color rgba="0 0 0 1"/>
      </material>
    </visual>
  </link>
  <link name="wheel_right">
    <visual>
      <geometry>
        <cylinder radius="0.05" length="0.02"/>
      </geometry>
      <material name="black">
        <color rgba="0 0 0 1"/>
      </material>
    </visual>
  </link>
  <joint name="base_to_wheel_left" type="continuous">
    <parent link="base_link"/>
    <child link="wheel_left"/>
    <origin xyz="-0.2 -0.15 0"/>
    <axis xyz="0 1 0"/>
  </joint>
  <joint name="base_to_wheel_right" type="continuous">
    <parent link="base_link"/>
    <child link="wheel_right"/>
    <origin xyz="-0.2 0.15 0"/>
    <axis xyz="0 1 0"/>
  </joint>
</robot>

